Workbook

Sheet 药品通数据
A1: 药品名称 | B1: 指导价 | C1: 处方药 | D1: 成分 | E1: 性状 | F1: 适应症 | G1: 用法用量 | H1: 不良反应 | I1: 禁忌 | J1: 注意事项 | K1: 特殊人群用药 | L1: 药物相互作用 | M1: 药理作用 | N1: 贮藏 | O1: 规格 | P1: 包装规格 | Q1: 有效期
A2: 通用名称：小儿氨酚黄那敏颗粒 商品名称：护彤 英文名称：Pediatric Paracetamol，Atificial Cow-bezoar and Chlorphenamine Maleate Granules 汉语拼音：Xiaoer Anfennamin Keli | B2: 8.4 | C2: =IF(ISNUMBER(MATCH(#REF!,非处方药名称!A:A,0)),"非处方药","处方药") -> 处方药 | D2: 本品为复方制剂，每袋含对乙酰氨基酚125毫克，马来酸氯苯那敏0.5毫克，人工牛黄5毫克。辅料为：蔗糖、阿司帕坦、甜菊素、食用香精 | E2: 本品为淡黄色至黄色或淡橙黄色颗粒。 | F2: 适用于缓解儿童普通感冒及流行性感冒引起的发热、头痛、四肢酸痛、打喷嚏、流鼻涕、鼻塞、咽痛等症状。 | G2: 温开水冲服。12岁以下儿童用量见下表：2～3岁， 12～14公斤， 0.5～1片/次， 一日3次4～6岁， 16～20公斤， 1～1.5片/次， 一日3次7～9岁， 22～26公斤， 1.5～2片/次， 一日3次10～12岁， 28～32公斤，2～2.5片/次， 一日3次 | H2: 有时有轻度头晕、乏力、恶心、上腹不适、口干、食欲缺乏和皮疹等，可自行恢复。 | I2: 严重肝肾功能不全者禁用。 | J2: 1.用药3-7天，症状未缓解，请咨询医师或药师。 2.服用本品期间不得饮酒或含有酒精的饮料。 3.1岁以下儿童应在医师指导下使用。 4.不能同时服用与本品成份相似的其他抗感冒药。 5.肝、肾功能不全者慎用。 6.如服用过量或出现严重不良反应，应立即就医。 7.对本品过敏者禁用，过敏体质者慎用。 8.本品性状发生改变时禁止使用。 9.请将本品放在儿童不能接触的地方。 10.儿童必须在成人监护下使用。 11.如正在使用其他药品，使用本品前请咨询医师或药师。 | K2: 儿童注意事项： 新生儿或早产儿禁用。 妊娠与哺乳期注意事项： 本品中对乙酰氨基酚，人工牛黄均可通过胎盘，可能会对胎儿造成不良影响，对胚胎有毒性且能致畸；除人工牛黄不详外，均能通过乳汁分泌，故孕妇及哺乳期妇女禁用。 老人注意事项： 尚不明确。 | L2: 1.与其他解热镇痛药同用，可增加肾毒性的危险。2.本品不宜与氨酶素等并用。3.如与其他药物同时使用可能会发生药物相互作用，详情请咨询医师或药师。 | M2: 本品中对乙酰氨基酚能抑制前列腺素合成，有解热镇痛作用；马来酸氯苯那敏为抗组胺药，能减轻流涕、鼻塞、打喷嚏等症状；人工牛黄有解热镇惊作用。 | N2: 密封，在阴凉干燥处保存。 | O2: 对乙酰氨基酚0.125克,人工牛黄5毫克,马来酸氯苯那敏0.5毫克 | Q2: 24个月。
A3: 通用名称：复方氨酚烷胺片 商品名称：感叹号 英文名称：Compound Paracetamol and Amantadine Hydrochloride Tablets 汉语拼音：Fu Fang An Fen Wan An Pian | B3: 10.6 | C3: =IF(ISNUMBER(MATCH(#REF!,非处方药名称!A:A,0)),"非处方药","处方药") -> 处方药 | D3: 本品为复方制剂，每片含对乙酰氨基酚250毫克，盐酸金刚烷胺100毫克，人工牛黄10毫克，咖啡因15毫克，马来酸氯苯那敏2毫克，辅料为：淀粉、硬脂酸镁。 | E3: 本品为淡黄色片。 | F3: 用于缓解普通感冒或流行性感冒引起的发热、头痛、咽痛、鼻塞、打喷嚏等症状。 | G3: 口服。成人，一次1片，一日2次。 | H3: 偶见粒细胞、血小板减少、厌食、恶心、呕吐、皮疹等不良反应。 | I3: 1对本品过敏者禁用。 2.活动性消化道溃疡患者禁用。 3.孕妇、哺乳期妇女禁用。 4.1岁以下儿童禁用。 | J3: 1. 用药3-7天，症状未缓解，请咨询医师或药师。 2. 服用本品期间不得饮酒或含有酒精的饮料。 3. 不能同时服用与本品成份相似的其他抗感冒药。 4. 肝功能不全、肾功能不全、脑血管病史、精神病史或癫痫病史患者慎用。 5. 前列腺肥大、青光眼等患者以及老年人应在医师指导下使用。 6. 孕妇及哺乳期妇女慎用。 7. 服药期间不得驾驶机、车、船、从事高空作业、机械作业及操作精密仪器。 8. 如服用过量或出现严重不良反应，应立即就医。 9. 对本品过敏者禁用，过敏体质者慎用。 10. 本品性状发生改变时禁止使用。 11. 请将本品放在儿童不能接触的地方。 12. 儿童必须在成人监护下使用。 13. 如正在使用其他药品，使用本品前请咨询医师或药师。 | K3: 儿童注意事项： 1岁以下儿童禁用。 妊娠与哺乳期注意事项： 本品中金刚烷胺、对乙酰氨基酚、人工牛黄均可通过胎盘，对胚胎有毒性且能致畸，可能会对胎儿造成不良影响;除人工牛黄不详外，均能通过乳汁分泌，故孕妇及哺乳期妇女禁用。 老人注意事项： 慎用或适当减量。 | L3: 1 与其他解热镇痛药同用，可增加肾毒性的危险; 2 本品不宜与氯霉素、巴比妥类(如苯巴比妥)等并用; 3 如与其他药物同时使用可能会发生药物相互作用，详情请咨询医师或药师。 | M3: 对乙酰氨基酚能抑制前列腺素合成，有解热镇痛的作用；金刚烷胺可抗“亚一甲型”流感病毒，抑制病毒繁殖；咖啡因为中枢兴奋药，能增强对乙酰氨基酚的解热镇痛效果，并能减轻其他药物所致的嗜睡、头晕等中枢抑制作用；马来酸氯苯那敏为抗过敏药，能减轻流涕、鼻塞、打喷嚏等症状；人工牛黄具有解热、镇惊作用。上述诸药配伍制成复方，可增强解热、镇痛效果，解除或改善感冒所引起的各种症状。 | N3: 密闭，阴凉干燥处保存。 | P3: 12s | Q3: 36个月
A4: 通用名称：苄达赖氨酸滴眼液 商品名称：莎普爱思 英文名称：Bendazac Lysine Eye Drops 汉语拼音：Biɑndɑlɑiɑnsuɑn Diyɑnye | B4: 106.6 | C4: =IF(ISNUMBER(MATCH(#REF!,非处方药名称!A:A,0)),"非处方药","处方药") -> 处方药 | D4: 本品每瓶含苄达赖氨酸25毫克。辅料为羟丙甲纤维素、磷酸二氢钠、磷酸氢二钠、氯化钠、硫柳汞（汞类化合物，0.001%）。 | E4: 本品为无色或几乎无色的澄明液体 | F4: 早期老年性白内障 | G4: 滴眼，一日3次，一次1～2滴或遵医嘱。 | H4: 一过性灼烧感，流泪等反应，但能随着用药时间延长而适应。极少可有吞咽困难，恶心，呕吐，腹泻,流泪，接触性皮炎等。 | I4: 眼外伤及严重感染时，暂不使用，或遵医嘱 | J4: 1、滴眼时请勿使管口接触手和眼睛，避免污染瓶内眼药水。2、使用后请控紧瓶盖，以防污染。3、部分病例出现一过性刺激感，如灼热感、刺痛等，但不影响使用。实验证明本品经冰箱冷藏(4℃左右)后可以降低刺激性的发生率和强度。建议使用时有刺激的患者，将本品放入冰箱冷藏后使用以降低刺激。若发现药水污染或混浊请弃去不用。4、据报导，一过性刺激的发生率和强度与眼部的其他感染或炎症有关，建议眼部有感染或炎症的白内障患者在使用本品时，最好在医师指导下同时治疗上述眼疾。5、对本品过敏者禁用，过敏体质者慎用。6、本品性状发生改变时禁止使用。7、请将本品放在儿童不能接触的地方。8、如正在使用其他药品，使用本品前请咨询医师或药师。 | K4: 儿童注意事项： 尚未明确。 妊娠与哺乳期注意事项： 尚未明确。 老人注意事项： 尚未明确。 | L4: 如与其他药物同时使用可能会发生药物相互作用，详情请咨询医师或药师 | M4: 本品是醛糖还原酶（AR）抑制剂，文献报告对晶状体醛糖还原酶（AR）有抑制作用，所以用苄达赖氨酸（BDZL）滴眼液抑制眼睛中AR的活性，达到预防或治疗白内障的目的。 | N4: 避光，密闭保存。 | O4: 5毫升:25毫克 | Q4: 36个月
A5: 通用名称：小儿感冒颗粒 英文名称：XiaoErGanMaoKeLi 汉语拼音：Xiaoer Ganmao Keli | C5: =IF(ISNUMBER(MATCH(#REF!,非处方药名称!A:A,0)),"非处方药","处方药") -> 处方药 | D5: 广藿香、菊花、连翘、大青叶、板蓝根、地黄、地骨皮、白薇、薄荷、石膏；辅料为蔗糖、糊精。 | E5: 本品为浅棕色的颗粒；味甜、微苦。 | F5: 疏风解表，清热解毒。用于小儿风热感冒，症见发热、头胀痛、咳嗽痰黏、咽喉肿痛；流感见上述证候者。 | G5: 开水冲服。一岁以内一次6克，一岁至三岁一次612克，四岁至七岁一次12-18克，八岁至十二岁一次24克，一日2次。 | H5: 尚不明确。 | I5: 尚不明确。 | J5: 1.忌辛辣、生冷、油腻食物。2.不宜在服药期间同时服用滋补性中药。3.婴儿应在医师指导下服用。4.风寒感冒者不适用。5.糖尿病患儿、脾虚易腹泻者应在医师指导下服用。6.发热体温超过38．5℃的患者，应去医院就诊。7.服药3天症状无缓解，应去医院就诊。8.对本品过敏者禁用，过敏体质者慎用。9.本品性状发生改变时禁止使用。10.儿童必须在成人监护下使用。11.请将本品放在儿童不能接触的地方。12.如正在使用其他药品，使用本品前请咨询医师或药师。13.开水冲泡，搅拌呈混悬状服用。 | L5: 如与其他药物同时使用可能会发生药物相互作用，详情请咨询医师或药师。 | M5: 疏风解表，清热解毒。 | N5: [02]药品阴凉贮存区(20℃以下) | O5: 12克/袋;6克/袋 | P5: 盒装，内小袋装。
A6: 通用名称：清咽滴丸 商品名称：松栢 英文名称：QingYanDiWan(SongBai) 汉语拼音：Qing Yan Di Wan | B6: 32 | C6: =IF(ISNUMBER(MATCH(#REF!,非处方药名称!A:A,0)),"非处方药","处方药") -> 处方药 | D6: 薄荷脑、青黛、冰片、诃子、甘草、人工牛黄。辅料为聚乙二醇。 | E6: 本品为棕褐色至黑褐色的滴丸；味微苦涩，气辛凉。 | F6: 疏风清热，解毒利咽。用于风热喉痹，咽痛，咽干，口渴；或微恶风，发热，咽部红肿，急性咽炎见上述证候者。 | G6: 含服。一次4～6粒，日3次。 | H6: 尚不明确。 | I6: 尚不明确。 | J6: 1.忌辛辣、鱼腥食物。 2.孕妇慎用。 3.不宜在服药期间同时服用温补性中成药。 4.服药三天后症状无改善，或出现其他症状，应去医院就诊。 5.按照用法用量服用，儿童应在医师指导下服用。 6.药品性状发生改变时禁止服用。 7.儿童必须在成人的监护下使用。 8.请将此药品放在儿童不能接触的地方。 9.如正在服用其他药物，使用本品前请咨询医师或药师。 10.对本品过敏者禁用，过敏体质者慎用。 | K6: 妊娠与哺乳期注意事项： 孕妇慎用。 | L6: 如与其他药物同时使用可能会发生药物相互作用，详情请咨询医师或药师。 | M6: 研究证实，清咽滴丸确有明显的抗炎和镇痛作用，对金黄色葡萄球菌等8株菌有一定的抑制作用。抗炎、镇痛、抑菌是本品治疗急性咽喉炎的药理基础。 | N6: 密封，置阴凉干燥处。 | O6: 每丸重20毫克 | P6: 瓷瓶装，50丸×2瓶。 | Q6: 36个月。
A7: 通用名称：感冒清片 英文名称：GanMaoQingPian 汉语拼音：Ganmaoqing Pian | B7: 3.1 | C7: =IF(ISNUMBER(MATCH(#REF!,非处方药名称!A:A,0)),"非处方药","处方药") -> 处方药 | D7: 南板蓝根、大青叶、金盏银盘、岗梅、山芝麻、对乙酰氨基酚、穿心莲叶、盐酸吗啉胍、马来酸氯苯那敏。 | E7: 本品为薄膜衣片，除去包衣后显灰绿色或灰褐色；味苦。 | F7: 疏风解表，清热解毒。用于风热感冒，发烧，头痛，鼻塞流涕，喷嚏，咽喉肿痛，全身酸痛等症。 | G7: 口服。一次3～4片，一日3次。 | H7: 尚不明确。 | I7: 尚不明确。 | J7: 用药期间不宜驾驶车辆、管理机器及高空作业等。 | L7: 如正在服用其他药品，使用本品前请咨询医师或药师。 | N7: 密封。 | O7: 每素片重0.22g(含对乙酰氨基酚12mg) | Q7: 24月
A8: 通用名称：口炎清颗粒 商品名称：大神 英文名称：KouYanQingKeLi(BaiYunShan) 汉语拼音：Kouyanqing Keli | B8: 18.3 | C8: =IF(ISNUMBER(MATCH(#REF!,非处方药名称!A:A,0)),"非处方药","处方药") -> 处方药 | D8: 天冬、麦冬、玄参、山银花、甘草。 | E8: 本品为棕黄色的颗粒；味甜、微苦。 | F8: 滋阴清热，解毒消肿。用于阴虚火旺所致的口腔炎症。 | G8: 口服。一次2袋，一日1～2次。 | H8: 尚不明确。 | I8: 尚不明确。 | J8: 1.忌烟、酒及辛辣、油腻食物。 2.糖尿病患者及有高血压、心脏病、肝病、肾病等慢性病严重者应在医师指导下服用。 3.儿童、孕妇、哺乳期妇女、年老体弱、脾虚便溏者应在医师指导下服用。 4.服药3天症状无缓解，应去医院就诊。 5.对本品过敏者禁用，过敏体质者慎用。 6.本品性状发生改变时禁止使用。 7.儿童必须在成人监护下使用。 8.请将本品放在儿童不能接触的地方。 9.如正在使用其他药品，使用本品前请咨询医师或药师。 | L8: 如与其他药物同时使用可能会发生药物相互作用，详情请咨询医师或药师。 | N8: 密封。 | O8: 每袋装3g(无蔗糖) | P8: 3克×10袋。 | Q8: 24个月。
A9: 通用名称：清开灵颗粒 商品名称：白云山 英文名称：QingKaiLingKeLi(BaiYunShan) 汉语拼音：Qing Kai Ling Ke Li | B9: 13 | C9: =IF(ISNUMBER(MATCH(#REF!,非处方药名称!A:A,0)),"非处方药","处方药") -> 处方药 | D9: 胆酸、珍珠母、猪去氧胆酸、栀子、水牛角、板蓝根、黄芩苷、金银花。 | E9: 本品为棕色的颗粒;味甜，微苦。 | F9: 清热解毒，镇静安神。对温热病引起的高热不退，烦燥不安，咽喉肿痛，舌红或绛，苔黄，脉数者适宜；多用于湿热型肝炎和上呼吸道感染症。 | G9: 口服。一次1～2袋，一日2～3次。 | H9: 尚不明确。 | I9: 孕妇禁用；糖尿病患者禁服。 | J9: 1.忌烟、酒及辛辣、生冷、油腻食物。 2.不宜在服药期间同时服滋补性中药。 3.发高烧体温超过38.5℃的患者，请上医院就诊；脾胃虚寒泄泻者慎服。 4.风寒感冒者不适用，其表现为恶寒重，发热轻，无汗，头痛，鼻塞，流清涕，喉痒咳嗽。 5.高血压、心脏病、肝病、肾病、糖尿病等慢性病严重者应在医生指导下服用。 6.服药3天症状无缓解，应去医院就诊。 7.儿童、年老体弱者应在医师指导下服用。 8.对本品过敏者禁用，过敏体质者慎用。 9.本品性状发生改变时禁止使用。 10.儿童必须在成人监护下使用。 11.请将本品 | L9: 如与其他药物同时使用可能会发生药物相互作用，详情请咨询医师或药师。 | M9: 经动物试验表明，清开灵有良好的退热和抗感染作用，并且能增加肝脏酶类的活性，提高肝脏解毒能力，起到治疗肝脏疾病的作用。 | N9: 密封。 | O9: 每袋装3克；10克(含黄芩苷20毫克) | P9: 3g*12袋
A10: 通用名称：连花清瘟胶囊 商品名称：以岭 英文名称：LianHuaQingWenJiaoNang(YiLing) 汉语拼音：Lianhua Qingwen Jiaonang | B10: 15 | C10: =IF(ISNUMBER(MATCH(#REF!,非处方药名称!A:A,0)),"非处方药","处方药") -> 处方药 | D10: 连翘、金银花、炙麻黄、炒苦杏仁、石膏、板蓝根、绵马贯众、鱼腥草、广藿香、大黄、红景天、薄荷脑、甘草。辅料为：淀粉。 | E10: 本品为胶囊剂，内容物为棕黄色至黄褐色的颗粒和粉末：气微香，味微苦。 | F10: 清瘟解毒，宣肺泄热。用于治疗流行性感冒属热毒袭肺证，症见：发热或高热，恶寒，肌肉酸痛，鼻塞流涕，咳嗽，头痛，咽干咽痛，舌偏红，苔黄或黄腻等。 | G10: 口服。一次4粒，一日3次。 | H10: 尚不明确。 | I10: 尚不明确。 | J10: 1.忌烟、酒及辛辣、生冷、油腻食物。 2.不宜在服药期间同时服用滋补性中药。 3.风寒感冒者不适用。 4.高血压、心脏病患者慎用。有肝病、糖尿病、肾病等慢性病严重者应在医师指导下服用。 5.儿童、孕妇、哺乳期妇女、年老体弱及脾虚便溏者应在医师指导下服用。 6.发热体温超过38.5℃的患者，应去医院就诊。 7.严格按用法用量服用，本品不宜长期服用。 8.服药3天症状无缓解，应去医院就诊。 9.对本品过敏者禁用，过敏体质者慎用。 10.本品性状发生改变时禁止使用。 11.儿童必须在成人监护下使用。 12.请将 | L10: 如与其他药物同时使用可能会发生药物相互作用，详情请咨询医师或药师。 | N10: 密封，置阴凉干燥处(不超过20℃)。 | O10: 每粒装0.35克 | P10: 铝塑板装。每盒24粒。 | Q10: 24个月
A11: 通用名称：止咳宝片 商品名称：特一 英文名称：ZhiKeBaoPian(TeYi) 汉语拼音：Zhikebao Pian | B11: 22 | C11: =IF(ISNUMBER(MATCH(#REF!,非处方药名称!A:A,0)),"非处方药","处方药") -> 处方药 | D11: 紫菀、橘红、桔梗、前胡、枳壳、百部、五味子、罂粟壳浸膏、甘草、薄荷素油、氯化铵等味。 | E11: 本品为包衣片，除去包衣后，显棕黑色；味微苦、咸。 | F11: 宣肺祛痰，止咳平喘。用于外感风寒所致的咳嗽、痰多清稀、咳甚而喘；慢性支气管炎、上呼吸道感染见上述证候者。 | G11: 口服。一次2片，一日3次；或遵医嘱。该药品连服七日为一疗程，可以连续服用三至五个疗程。 | H11: 尚不明确。 | I11: 孕妇、婴儿及哺乳期妇女忌服。 | J11: 1.忌烟、酒及辛辣、生冷、油腻食物。 2.服药期间不宜再受风寒。 3.不宜在服药期间同时服用滋补性中药。 4.肺热、肺燥之干咳及咳痰带血者慎用。 5.该药品含氯化铵，肝肾功能异常者及老年患者慎用。消化性溃疡患者应在医师指导下使用。 6.支气管扩张、肺脓疡、肺心病、肺结核患者出现咳嗽时应去医院就诊。 7.有高血压、心脏病、糖尿病等慢性病严重者应在医师指导下服用。 8.儿童应在医师指导下服用。 9.服药期间，若患者发热体温超过38.5℃，或出现喘促气急者，或咳嗽加重、痰量明显增多者应去医院就诊 | L11: 如与其他药物同时使用可能会发生药物相互作用，详情请咨询医师或药师。 | N11: 密封，置阴凉干燥处 | O11: 每片重0.35克 | Q11: 24月
A12: 通用名称：感冒灵胶囊 商品名称：999 英文名称：GanMaoLingJiaoNang(999) 汉语拼音：Ganmaoling Jiaonang | B12: 15.8 | C12: =IF(ISNUMBER(MATCH(#REF!,非处方药名称!A:A,0)),"非处方药","处方药") -> 处方药 | D12: 三叉苦、岗梅、金盏银盘、薄荷油、野菊花、马来酸氯苯那敏、咖啡因、对乙酰氨基酚。 | E12: 本品为胶囊剂，内容物为棕褐色颗粒；味苦。 | F12: 用于感冒引起的头痛，发热，鼻塞，流涕，咽痛等。 | G12: 口服。一次2粒，一日3次。 | H12: 可见困倦、嗜睡、口渴、虚弱感；偶见皮疹、荨麻疹、药热及粒细胞减少；长期大量用药会导致肝肾功能异常。 | I12: 严重肝肾功能不全者禁用。 | J12: 1.忌烟、酒及辛辣、生冷、油腻食物。 2.不宜在服药期间同时服用滋补性中成药。 3.本品含对乙酰氨基酚、马来酸氯苯那敏、咖啡因。服用本品期间不得饮酒或含有酒精的饮料；不能同时服用与本品成份相似的其他抗感冒药；肝、肾功能不全者慎用；膀胱颈梗阻、甲状腺功能亢进、青光眼、高血压和前列腺肥大者慎用；孕妇及哺乳期妇女慎用；服药期间不得驾驶机、车、船、从事高空作业、机械作业及操作精密仪器。 4.脾胃虚寒，症见腹痛、喜暖、泄泻者慎用。 5.心脏病、糖尿病等慢性病严重者应在医师指导下服用。 6.儿童、年老体弱者应在医师指导下服用。 7.服药3天后症状无改善，或症状加重，或出现新的严重症状如胸闷、心悸等应立即停药，并去医院就诊。 8.对本品过敏者禁用，过敏体质者慎用。 9.本品性状发生改变时禁止使用。 10.儿童必须在成人监护下使用。 11.请将本品放在儿童不能接触的地方。 12.如正在使用其他药品，使用本品前请咨询医师或药师。 | L12: 1 与其他解热镇痛药并用，有增加肾毒性的危险。2 如与其他药物同时使用可能会发生药物相互作用，详情请咨询医师或药师。 | M12: 解热镇痛。 | N12: 密封 | O12: 每粒装0.5g(含对乙酰氨基酚0.1g) | P12: 12粒
A13: 通用名称：补肾固齿丸 商品名称：九芝堂 英文名称：BuShenGuChiWan(JiuZhiTang) 汉语拼音：Bushen Guchi Wan | B13: 45.2 | C13: =IF(ISNUMBER(MATCH(#REF!,非处方药名称!A:A,0)),"非处方药","处方药") -> 处方药 | D13: 熟地黄、地黄、鸡血藤、紫河车、盐骨碎补、漏芦、酒丹参、酒五味子、山药、醋郁金、炙黄芪、牛膝、野菊花、茯苓、枸杞子、牡丹皮、盐泽泻、肉桂。辅料：食盐、薄膜包衣剂。 | E13: 本品为薄膜衣水丸，除去包衣后显棕褐色；味咸、微苦、辛。 | F13: 补肾固齿，活血解毒。用于肾虚血热型牙周病，牙齿酸软，咀嚼无力，松动移位，牙龈出血。 | G13: 口服。一次4克，一日2次。 | H13: 尚不明确。 | I13: 尚不明确。 | J13: 1.忌烟、酒及辛辣、油腻食物。 2.不宜在服药期间同时服用温补性中药。 3.儿童、哺乳期妇女、年老体弱者应在医师指导下服用。 4.有高血压、心脏病、肝病、肾病等慢性病严重者应在医师指导下服用。 5.服药时最好配合牙科治疗。 6.服药7天症状无缓解，应去医院就诊。 7.对本品过敏者禁用，过敏体质者慎用。 8.药品性状发生改变时禁止服用。 9.儿童必须在成人监护下使用。 10.请将此药品放在儿童不能接触的地方。 11.如正在服用其他药品，使用本品前请咨询医师或药师。 | K13: 妊娠与哺乳期注意事项： 孕妇禁用。 | L13: 如与其他药物同时使用可能会发生药物相互作用，详情请咨询医师或药师。 | N13: 密闭，置阴凉干燥处。 | O13: 每30丸重1克
A14: 通用名称：小儿热速清颗粒 商品名称：圣泰 英文名称：XiaoErReSuQingKeLi(ShengTai) 汉语拼音：Xiao Er Re Su Qing Ke Li | B14: 19.5 | C14: =IF(ISNUMBER(MATCH(#REF!,非处方药名称!A:A,0)),"非处方药","处方药") -> 处方药 | D14: 柴胡、黄芩、板蓝根、葛根、金银花、水牛角、连翘、大黄。辅料为蔗糖、糊精。 | E14: 本品为土黄色至棕褐色的颗粒;味微苦。 | F14: 清热，解毒，利咽。用于风热感冒，发热头痛，咽喉红肿，鼻塞流黄涕，咳嗽，便秘。 | G14: 口服。一岁以内，一次1/4-半袋，一岁至三岁，一次半袋-1袋，三岁至七岁，一次1袋-1.5袋，七岁至十二岁，一次1.5袋-2袋，一日3-4次。 | H14: 尚不明确。 | I14: 风寒感冒，大便次数多者忌用。 | J14: 1.感冒风寒，大便次数多者忌用。2.忌食生冷辛辣食物。3.按照用法用量服用，如病情较重或服药二天后疗效不明显者，应及时去医院就诊。4.药品性状发生改变时禁止服用。5.儿童必须在成人的监护下使用。6.请将此药品放在儿童不能接触的地方。7.如正在服用其他药品，使用本品前请咨询医师或药师。 | L14: 如正在服用其他药品，使用本品前请咨询医师或药师。 | M14: 清热，解毒，利咽。 | N14: 密封。 | O14: 每袋装2克 | P14: 2g*6袋/盒
A15: 通用名称：小儿肺热咳喘颗粒4克 商品名称：葫芦娃 汉语拼音：Xiaoer Feire Kechuan Keli | C15: =IF(ISNUMBER(MATCH(#REF!,非处方药名称!A:A,0)),"非处方药","处方药") -> 处方药 | D15: 麻黄、苦杏仁、生石膏、甘草、金银花、连翘、知母、黄芩、板蓝根、麦冬、鱼腥草。 | E15: 本品为棕黄色至深棕黄色颗粒；味甜 | F15: 清热解毒，宣肺止咳，化痰平喘。用于感冒，支气管炎，喘息性支气管炎，支气管肺炎属痰热壅肺证者。 | G15: 开水冲服，三周岁以下一次4克（一袋），一日3次；三周岁以上一次4克（一袋），一日4次；七周岁以上一次8克（2袋），一日3次。 | H15: 大剂量服用，可能有轻度胃肠不适反应。 | I15: 尚不明确 | J15: 1.忌辛辣、生冷、油腻食物。2.不宜在服药期间同时服用滋补性中药。3.婴儿及糖尿病患儿应在医师指导下服用。4.风寒闭肺、内伤久咳者不适用。5.运动员慎用。6.高血压、心脏病患儿慎用。脾虚易腹泻者在医师指导下服用。7.发热体温超过38.5℃的患者，应去医院就诊。8.服药3天症状无缓解，应去应用就诊。9.对本品过敏者禁用，过敏体质者慎用。10.本品性状发生改变时禁止使用。11.儿童必须在成人监护下使用。12.请将本品放在儿童不能接触的地方。13.如正在使用其他药品，使用本品前请咨询医师或药师。 | L15: 如与其他药物同时使用可能会发生药物相互作用，详情请咨询医师或药师。 | N15: 密封 | P15: 每袋装4克(相当于饮片10.6克) | Q15: 30个月
A16: 通用名称：熊胆川贝口服液 商品名称：一品红 英文名称：XiongDanChuanBeiKouFuYe(YiPinHong) 汉语拼音：Xiongdan Chuanbei Koufuye | B16: 22.5 | C16: =IF(ISNUMBER(MATCH(#REF!,非处方药名称!A:A,0)),"非处方药","处方药") -> 处方药 | D16: 熊胆、川贝母、杏仁 | E16: 本品为浅黄色至浅黄棕色的液体；气微香，味甜微苦、有凉喉感。 | F16: 清热化痰，止咳。用于痰热咳嗽，咳痰不止，咯痰不爽。 | G16: 口服。一次10毫升，一日2-3次。 | H16: 尚不明确。 | I16: 孕妇禁用；糖尿病患者禁服。 | J16: 1.忌食辛辣、油腻食物。 2.本品适用于肺热咳嗽，其表现为咳嗽，咯痰不爽，痰粘稠。 3.支气管扩张、肺脓疡、肺心病、肺结核患者应在医师指导下服用。 4.服用一周病证无改善，应停止服用，去医院就诊。 5.服药期间，若患者出现高热，体温超过38℃，或出现喘促气急者，或咳嗽加重，痰量明显增多者应到医院就诊。 6.孕妇、体质虚弱者慎用。 7.对本品过敏者禁用，过敏体质者慎用。 8.药品性状发生改变时禁止服用。 9.儿童必须在成人监护下使用。 10.请将此药品放在儿童不能接触的地方。 11.如正在服用其他药品，使用本品前请咨询医师或药师。 | L16: 如与其他药物同时使用可能会发生药物相互作用，详情请咨询医师或药师。 | N16: 密封 | O16: 每支装10毫升 | P16: 每盒6支，每盒6支，10支/盒，12支/盒 | Q16: 24个月
A17: 通用名称：盐酸卡替洛尔滴眼液 商品名称：美开朗 英文名称：Carteolol Hydrochloride Eye Drops 汉语拼音：Yansuan Katiluoer Diyanye | B17: 24.8 | C17: =IF(ISNUMBER(MATCH(#REF!,非处方药名称!A:A,0)),"非处方药","处方药") -> 处方药 | D17: 本品主要成份为：盐酸卡替洛尔。其化学名称为：5-[3-(1,1二甲基乙基)氨基]-2羟丙氧基-3,4-二氢-2（1H）-喹诺酮盐酸盐。分子式：C16H24N2O3HCl分子量：328.84 | E17: 本品为无色的澄明溶液。 | F17: 对原发性开角型青光眼具有良好的降低眼内压疗效。对于某些继发性青光眼，高眼压症，手术后未完全控制的闭角型青光眼以及其他药物及手术无效的青光眼，加用本品滴眼可进一步增强降眼压效果。 | G17: 滴眼，一日2次，一次1滴。滴于结膜囊内，滴后用手指压迫内毗角泪囊部3～5分钟。 | H17: 1.1/4的患者出现暂时性眼烧灼，眼刺痛及流泪，结膜充血水肿. 2.一些患者出现下列不良反应：视物模糊，畏光，上睑下垂，结膜炎，角膜着色及中度角膜麻醉。 3.长期连续用于无晶体眼或有眼底疾患者时，偶在眼底黄斑部出现浮肿，混浊，故需定期测定视力，进行眼底检查。 4.一些患者出现心率减慢及血压下降。 5.偶见下列不良反应：心率失常，心悸，呼吸困难，无力，头痛，头晕，失眠，鼻窦炎。 6.应用本品还有以下非常罕见不良反应： （1）全身症状：头痛。 （2）心血管系统：心率失常，晕厥，心传导阻滞，脑血管意外，脑缺血， | I17: 1 支气管哮喘者或有支气管哮喘史者，严重慢性阻塞性肺部疾病。 2 窦性心动过缓，Ⅱ或Ⅲ度房室传导阻滞，明显心衰，心源性休克。 3 对本品过敏者。 | J17: 1.本品慎用于已知是全身β-肾上腺能阻断剂禁忌症的患者，包括异常心动过缓，I度以上房室传导阻滞。 2.对有明显心脏疾病患者应用本品应监测脉搏。 3.本品慎用于对其他β-肾上腺能阻断剂过敏者。 4.已有肺功能低下的患者慎用。 5.本品慎用于自发性低血糖患者及接受胰岛素或降糖药治疗的患者，因β受体阻滞剂可掩盖低血糖症状。 6.本品不易单独用于治疗闭角型青光眼。 7.与其他滴眼液联合使用时，请间隔10分钟以上。 8.本品含氯化苯烷铵戴软性角膜接触镜者不宜使用。 9.定期复查眼压，根据眼压变化调整用药方案。 10 | K17: 儿童注意事项： 本品对于儿童的安全性和疗效尚未确立，请慎用。 妊娠与哺乳期注意事项： 本品对于孕妇的安全性尚未确立，孕妇应慎用。尚不清楚本品是否通过乳汁分泌，已知同类药物马来酸噻吗洛尔滴眼液滴眼后可在哺乳期妇女乳汁中测到，且对授乳婴儿具有多种潜在不良反应，所以哺乳期妇女应权衡利弊，在医生指导下使用。 老人注意事项： 尚不明确。 | L17: 1 与肾上腺素合用可引起瞳孔扩大。 2 正在服用儿茶酚胺耗竭药（如利血平）者，使用本品时应严密观察，因可引起低血压和明显的心动过缓。 3 不主张两种局部&beta;受体阻断剂同时应用，对正在应用&beta;受体阻断剂口服治疗的患者应慎用本品。 4 本品与钙通道拮抗剂合用应慎重，因可引起房室传导阻滞，左心室衰竭及低血压。对心功能受损的患者，应避免两种药合并使用。 5 本品与洋地黄类和钙通道拮抗剂合用可进一步延长房室传导时间。 6 酚噻嗪类药物可增加&beta;受体阻断剂的降血压作用，因可使相互的代谢途径受到抑制。 | M17: 药理作用： 1 盐酸卡替洛尔为非选择性&beta;-肾上腺受体阻断剂，对&beta;1和&beta;2受体均有阻断作用。盐酸卡替洛尔具有极小或不具有局麻作用。 2 卡替洛尔与其他&beta;受体阻断剂的主要区别在于它具有内在拟交感活性。 3 本品为盐酸卡替洛尔滴眼液，对高眼压和正常眼压患者均有降眼压作用，可使眼压下降22～25%。 4 卡替洛尔的主要代谢产物8-羟基-卡替洛尔是一种眼部&beta;受体阻断剂，也有降眼压作用，它可能与卡替洛尔降眼压作用持续时间较长有关。 5 本品的降眼压机制主要是减少房水生成，本品对房水经葡萄膜巩膜外流，房水流出易度及巩膜上静脉压无影响。非临床毒理研究： 致癌性：动物实验显示对大鼠和小鼠大量口服盐酸卡替洛尔连续2年不产生致癌毒性。致突变性：体内外动物实验未显示盐酸卡替洛尔有致突变活性。生殖毒性：动物实验显示大剂量口服盐酸卡替洛尔，对雄，雌性大鼠及小鼠的生殖功能均无影响。 | N17: 遮光，密闭保存。 | O17: 5毫升:100毫克 | Q17: 36月
A18: 通用名称：曲尼司特胶囊 商品名称：曲可伸 英文名称：Tranilast Capsules 汉语拼音：Qu Ni Si Te Jiao Nang | B18: 23.8 | C18: =IF(ISNUMBER(MATCH(#REF!,非处方药名称!A:A,0)),"非处方药","处方药") -> 处方药 | D18: 曲尼司特。 | E18: 胶囊。内含淡黄色粉末；无臭，无味。 | F18: 本品为抗变态反应药，可用于支气管哮喘及过敏性鼻炎的预防性治疗。 | G18: 口服。通常情况下，成人一日3次，一次1粒(0.1g);儿童一日5mg/kg，分3次服用。用于哮喘发作时与其他平喘药配伍用，或遵医嘱。 | H18: 1.肝脏：偶尔出现肝功能异常，需注意观察，可采取减量、停药等适当措施。 2.胃肠：有时发现食欲缺乏，恶心、呕吐、腹痛、腹胀、便秘、腹泻、胃部不适，偶有胃部不消化感。 3.血液：可有红细胞数和血色素量下降。 4.精神神经系统：头痛、嗜睡、偶尔头重、失眠、头昏、全身疲倦感等症状。 5.过敏反应：皮疹，偶见全身痒等过敏症状，此时应停药。 6.泌尿系统：偶见膀胱刺激症状，应停止用药。 7.其它：偶见心悸、浮肿、面部红晕、鼻出血、口腔炎等症状。 | I18: 1.孕妇忌用。 2.对本品成份过敏的患者禁用。 | J18: 1.本品能阻断过敏反应发生的环节，在哮喘好发季节前半月起服用，能起到预防作用。 2.本品不同于支气管舒张剂以及肾上腺皮质激素，对已经发作的哮喘症状，不能迅速起效。 3.本品可与其它平喘药并用，以本品作为基础处方药，有规则地服用。 4.激素依赖性患者使用本品时，激素用量应慢慢减少，不可突然停用。 5.肝、肾功能异常者慎用。 | K18: 儿童注意事项： 尚不明确。 妊娠与哺乳期注意事项： 1.妊娠（特别是3个月以内）和有可能妊娠的妇女，禁用。 2.哺乳妇女服用时应避免授乳。 老人注意事项： 尚不明确。 | L18: 与抗凝血药物华法令合用或终止合用时，可增强或减弱其作用并降低或增高血栓试验值，故在临床合用或终止合用时应注意观察凝血功能的变化。 | M18: 有稳定肥大细胞和嗜碱粒细胞的细胞膜作用，阻止其脱颗粒，从而抑制组胺、5-羟色胺过敏性反应物质的释放，对于1gE抗体引起的大白鼠皮肤过敏反应和实验性哮喘有显著抑制作用。 | N18: 密封，在干燥处保存。 | O18: 0.1克 | Q18: 36个月
A19: 通用名称：蓝芩口服液 商品名称：扬子江 英文名称：LanQinKouFuYe(YangZiJiang) 汉语拼音：Lanqin Koufuye | B19: 32.1 | C19: =IF(ISNUMBER(MATCH(#REF!,非处方药名称!A:A,0)),"非处方药","处方药") -> 处方药 | D19: 板蓝根、黄芩、栀子、黄柏、胖大海。 | E19: 本品为棕红色的澄清液体；味甜、微苦。 | F19: 清热解毒，利咽消肿。用于急性咽炎、肺胃实热证所致的咽痛、咽干、咽部灼热。 | G19: 口服。一次20毫升（2支），一日3次。 | H19: 个别患者服药后出现轻度腹泻，一般可自行缓解。 | I19: 尚不明确。 | J19: 1.忌烟酒。辛辣。鱼腥食物。 2.不宜在服药期间同时服用温补性中药。 3.孕妇慎用。糖尿病患者、儿童应在医师指导下服用。 4.脾虚大便溏者慎用。 5.属风寒感冒咽痛者，症见恶寒发热，无汗、鼻流清涕者慎用。 6.服药3天症状无缓解，应去医院就诊。 7.对本品过敏者禁用，过敏体质者慎用。 8.本品性状发生改变时禁止使用。 9.儿童必须在成人监护下使用。 10.请将本品放在儿童不能接触的地方。 11.如正在使用其他药品，使用本品前请咨询医师或药师。 | L19: 如与其他药物同时使用可能会发生药物相互作用，详情请咨询医师或药师。 | M19: 清热解毒，利咽消肿。 | N19: 密封，置阴凉处（不超过20℃），在贮藏期间允许有少量轻摇易散的沉淀。 | O19: 每支10毫升 | P19: 10ml*6支/盒
A20: 通用名称：四味珍层冰硼滴眼液 商品名称：珍视明 英文名称：siweizhencengbingpengdiyanye(zhenshimingdiyanye) 汉语拼音：Siweizhencenbinpeng Diyanye | B20: 21.2 | C20: =IF(ISNUMBER(MATCH(#REF!,非处方药名称!A:A,0)),"非处方药","处方药") -> 处方药 | D20: 珍珠层粉、天然冰片、硼砂、硼酸。辅料：氯化钠、乙醇、注射用水、苯氧乙醇。 | E20: 本品为近无色或微黄色的澄明液体。气香。 | F20: 清热解痉，去翳明目。用于肝阴不足，肝气偏盛所致的不能久视、青少年远视力下降；青少年假性近视、视力疲劳。 | G20: 滴于眼睑内。一次1-2滴，一日3-5次；必要时可酌情增加。 | H20: 尚不明确。 | I20: 尚不明确。 | J20: 1.本品为外用滴眼液，禁止内服。2.忌烟、酒、辛辣刺激性食物。3.眼部有炎症者应去医院就诊。4.用药后有沙涩磨痛、流泪频频、眼痒、眼睑皮肤潮红、眼胀者应停用，并到医院就诊。5.如视力下降明显应到医院就诊。6.滴眼时瓶口勿接触眼睛，使用后应将瓶盖拧紧，以免污染药液。7.用药7天症状无缓解，应去医院就诊。8.打开瓶盖后，15天内用完。9.对本品过敏者禁用，过敏体质者慎用。10.本品性状发生改变时禁止使用。11.儿童必须在成人监护下使用。12.请将本品放在儿童不能接触的地方。 | L20: 如与其他药物同时使用可能会发生药物相互作用，详情请咨询医师或药师。 | M20: 珍珠明目液由珍珠水解液与冰片配伍制成，珍珠水解液中主要成份为珍珠，珍珠具有镇心安神，养阴熄火，清热隧痰，去翳明目，解毒生肌的功能，现代药理学研究表明，珍珠具有延缓衰老，抗氧化作用，抗肿瘤作用，促进创面肉芽增生作用及降低心肌和脑组织脂褐素作用。 冰片具有通诸窍，散郁火，去翳明目，消肿止痛的功能。药理研究表明，龙脑具有明显的镇痛作用，抗炎作用及抗菌作用，局部应用对感觉神经有轻微刺激及上痛和防腐作用。冰片经粘膜，皮下组织均易吸收。 | N20: 密封，置凉暗处（避光并不超过20°C） | O20: 每瓶装8毫升;每瓶装13毫升;每瓶装15毫升 | P20: 塑料瓶，每小盒装一瓶。
A21: 通用名称：复方硫酸软骨素滴眼液 商品名称：润洁 英文名称：Compound Chondroitin Sulfate Eye Drops 汉语拼音：Fufang Liusuan Ruangaosu Diyanye | B21: 19.7 | C21: =IF(ISNUMBER(MATCH(#REF!,非处方药名称!A:A,0)),"非处方药","处方药") -> 处方药 | D21: 本品为复方制剂，其主要成分为每毫升含硫酸软骨素钠1毫克、维生素E0.1毫克、维生素B60.1毫克、尿囊素2毫克、牛磺酸2毫克。辅料为：玻璃酸钠、硼酸、硼砂、冰片、薄荷脑、无水乙醇、聚山梨酯80、三氯叔丁醇。 | E21: 本品为无色澄明或微带乳光的液体。 | F21: 用于视疲劳，干眼症。 | G21: 滴入眼内。一日4～6次，或有需要时滴眼;一次2～3滴。 | H21: 临床研究中报道偶有患者出现轻度眼分泌物增多及眼部不适感。 | I21: 尚不明确。 | J21: 1.本品仅供滴眼使用。 2.滴眼时请勿使管口接触手和眼睛，避免污染瓶内眼药水 3.若出现眼睛充血、发痒、红肿等较严重刺激症状时，应停止使用，并咨询医师或药师。 4.眼睛剧烈疼痛患者、青光眼患者使用前请咨询医生。 5.对本品过敏者禁用，过敏体质者慎用。 6.本品性状发生改变时禁止使用。 7.请将本品放在儿童不能接触的地方。 8.儿童必须在成人监护下使用。 9.如正在使用其他药品，使用本品前请咨询医师或药师。 | K21: 儿童注意事项： 尚不明确。 妊娠与哺乳期注意事项： 尚不明确。 老人注意事项： 尚不明确。 | L21: 如与其他药物同时使用可能会发生药物相互作用，详情请咨询医师或药师。 | M21: 硫酸软骨素为一种酸性粘多糖，是眼组织中的重要成份之一，具有促进角膜水分代谢、改善微循环、保护角膜并促进角膜组织损伤修复的功能，同时还可在角膜表面形成一层保护膜，防止水分散发，有效缓解视疲劳和干眼症状;牛磺酸除可抗菌消炎外，在眼组织内还参与多种生理活动，促进新陈代谢，改善视疲劳。 | N21: 密闭，在阴凉处。 | O21: 5ml;10ml | Q21: 24个月
A22: 通用名称：清热消炎宁胶囊 商品名称：敬修堂 英文名称：QingReXiaoYanNingJiaoNang(JingXiuTang) 汉语拼音：Qingrexiaoyanning Jiaonang | B22: 13.5 | C22: =IF(ISNUMBER(MATCH(#REF!,非处方药名称!A:A,0)),"非处方药","处方药") -> 处方药 | D22: 主要成分：丸节茶。 | E22: 本品为胶囊剂，内容物为黑褐色的粉末；味微苦、涩。 | F22: 清热解毒，消炎止痛，舒筋活络。适用于流行性感冒，咽喉炎，肺炎，细菌性痢疾，急性胃肠炎，阑尾炎，烧伤，疮疡脓肿，蜂窝组织炎。 | G22: 口服。一次2～4粒，一日3次。外用。将内容物加温开水溶化后，按患处大小搽敷，一日2～3次。 | H22: 尚不明确。 | I22: 尚不明确。 | J22: 1.忌烟、酒及辛辣、生冷、油腻食物。 2.不宜在服药期间同时服用滋补性中药。 3.发高烧体温超过38.5℃的患者，请上医院就诊。 4.高血压、心脏病、肝病、糖尿病、肾病等慢性病严重者应在医师指导下服用。 5.服药3天症状无缓解，应去医院就诊。 6.儿童、年老体弱者、孕妇应在医师指导下服用。 7.对本品过敏者禁用，过敏体质者慎用。 8.本品性状发生改变时禁止使用。 9.儿童必须在成人监护下使用。 10.请将本品放在儿童不能接触的地方。 11.如正在使用其他药品，使用本品前请咨询医师或药师。 | L22: 如与其他药物同时使用可能会发生药物相互作用，详情请咨询医师或药师。 | N22: 密封保存。 | O22: 每粒装0.32克 | Q22: 36个月。
A23: 通用名称：重感灵片 商品名称：嘉应 英文名称：ZhongGanLingPian(JiaYing) 汉语拼音：Zhongganmao Pian | B23: 6.5 | C23: =IF(ISNUMBER(MATCH(#REF!,非处方药名称!A:A,0)),"非处方药","处方药") -> 处方药 | D23: 毛冬青羌活葛根石膏马鞭草板蓝根青蒿马来酸氯苯那敏安乃近 | E23: 本品为黄色的糖衣片，除去糖衣后显棕褐色；味苦。 | F23: 解表清热，消炎止痛。用于治疗恶寒，高热，四肢酸痛，鼻塞，咽喉肿痛，咳嗽等重症感冒，流行性感冒，四时感冒的各种症状。 | G23: 口服。一次6～8片，一日3～4次。 | H23: 本品偶有粒细胞减少及过敏性皮疹反应 | I23: 尚不明确 | J23: 用药期间不宜驾驶车辆、管理机器及高空作业等。 | L23: 如与其他药物同时使用可能会发生药物相互作用，详情其咨询医师或药师。 | N23: 密封 | O23: 糖衣：每片含安乃近31.25毫克，马来酸氯苯那敏0.375毫克；薄膜衣：片重0.51克(含安乃近62.5毫克，马来酸氯苯那敏0.75毫克) | P23: 48片 | Q23: 36月
A24: 通用名称：氧氟沙星眼膏 商品名称：迪可罗 英文名称：Ofloxacin Eye Ointment 汉语拼音：Yangfu Shaxing Yangao | B24: 18.3 | C24: =IF(ISNUMBER(MATCH(#REF!,非处方药名称!A:A,0)),"非处方药","处方药") -> 处方药 | D24: 本品主要成分为：氧氟沙星。 | E24: 白色或类白色的软膏。 | F24: 适用于治疗细菌性结膜炎，角膜炎，角膜溃疡，泪囊炎，术后感染等外眼感染。 | G24: 局部用药:涂于眼睑内，一日3次，一次适量，或遵医嘱。 | H24: 偶尔有一过性刺激症状,不影响用药。 | I24: 对氧氟沙星或其它喹诺酮类药物过敏者禁用。 | J24: 1.品不宜长期使用。 2.用中出现过敏症状,应立即停止使用。 | K24: 儿童注意事项： 尚不明确。 妊娠与哺乳期注意事项： 尚不明确。 老人注意事项： 尚不明确。 | L24: 氧氟沙星与抗凝剂之间的相互作用不明显，本品与头孢噻肟、甲硝唑、克林霉素、环孢菌素等同用后，各药物的药动学过程均无明显改变。 | M24: 通过抑制细菌的DNA旋转酶和DNA复制而发挥作用。由于其独特的作用机理，具有抗菌谱广，抗菌活性强的特点，对革兰阳性菌，阴性菌群均有较强的抗菌作用。对葡萄球菌，化脓性链球菌，溶血性链球菌，肠球菌，肺炎球菌，大肠杆菌，柠檬酸细菌属，肺炎杆菌，肠菌属，沙雷氏菌属，变形杆菌属，铜绿假单胞菌，流感嗜血杆菌，不动杆菌属，弯曲杆菌属，衣原体属敏感性菌种等感染有效.本品与其他类抗菌药未见交叉耐药性。 | N24: 密封,在阴凉干燥处保存. | O24: 3.5克:10.5毫克 | Q24: 24个月
A25: 通用名称：咽炎片 商品名称：999 英文名称：YanYanPian(999) 汉语拼音：Yanyan Pian | B25: 15.8 | C25: =IF(ISNUMBER(MATCH(#REF!,非处方药名称!A:A,0)),"非处方药","处方药") -> 处方药 | D25: 玄参、板蓝根、天冬、麦冬、牡丹皮、百部(制)、青果、款冬花(制)、木蝴蝶、地黄、蝉蜕、薄荷油。 | E25: 本品为糖衣片;除去糖衣后显棕褐色，微苦、辛。 | F25: 养阴润肺，清热解毒，清利咽喉，镇咳止痒。用于慢性咽炎引起咽干，咽痒，刺激性咳嗽。 | G25: 口服。一次5片，一日3次。 | H25: 详见说明书。 | I25: 对本药品任何成分过敏者禁用。 | J25: 1 忌辛辣、鱼腥食物。 2 孕妇慎用。 3 服药七天后症状无改善，或出现其他症状，应去医院就诊。 4 按照用法用量服用，儿童应在医师指导下服用。 5 药品性状发生改变时禁止服用。 6 儿童必须在成人的监护下使用。 7 请将此药品放在儿童不能接触的地方。 8 如正在服用其他药物，使用本品前请咨询医师或药师。 | K25: 妊娠与哺乳期注意事项： 孕妇慎用。 | L25: 如与其他药物同时使用可能会发生药物相互作用，详情请咨询医师或药师。 | M25: 养阴润肺，清热解毒，清利咽喉，镇咳止痒。 | N25: 密封。 | O25: 每片重0.25克 | P25: 12粒*2板/盒 | Q25: 24个月
A26: 通用名称：喉疾灵胶囊 商品名称：陈李济 英文名称：HouJiLingJiaoNang(ChenLiJi) 汉语拼音：Houjiling Jiaonang | B26: 24.8 | C26: =IF(ISNUMBER(MATCH(#REF!,非处方药名称!A:A,0)),"非处方药","处方药") -> 处方药 | D26: 牛黄、板蓝根、山豆根、桔梗、诃子、了哥王、天花粉、连翘、冰片、珍珠层粉、广东土牛膝、猪牙皂。 | E26: 本品为胶囊剂，内容物为棕褐色的粉末；气芳香，味苦。 | F26: 清热，解毒，消肿止痛。用于扁桃体炎，急性咽炎，慢性咽炎急性发作。 | G26: 口服。一次3～4粒，一日3次。 | H26: 尚不明确。 | I26: 孕妇禁用。 | J26: 1 忌烟酒、辛辣、鱼腥食物。 2 不宜在用药期间同时服用温补性中药。 3 脾虚大便溏者慎用。 4 属风寒感冒咽痛者，症见恶寒发热、无汗、鼻流清涕者慎用。 5 严格按照用法用量服用，儿童、年老体弱者应在医师指导下服用。 6 扁桃体有化脓及全身高热者应去医院就诊。 7 服药3天症状无缓解，应去医院就诊。本品不宜长期服用。 8 对本品过敏者禁用，过敏体质者慎用。 9 本品性状发生改变时禁止使用。 10 儿童必须在成人监护下使用。 11 请将本品放在儿童不能接触的地方。 12 如正在使用其他药品，使用本品前请咨询医师或药师。 | L26: 如与其他药物同时使用可能会发生药物相互作用，详情请咨询医师或药师。 | M26: 尚不明确。 | N26: 密封。 | O26: 每粒装0.25克
A27: 通用名称：宣肺止嗽合剂 商品名称：普安康 英文名称：XuanFeiZhiSuHeJi(PuAnKang) 汉语拼音：Xuanfei Zhisu Heji | B27: 31 | C27: =IF(ISNUMBER(MATCH(#REF!,非处方药名称!A:A,0)),"非处方药","处方药") -> 处方药 | D27: 荆芥、前胡、桔梗、百部（蜜炙）、紫菀（蜜炙）、陈皮、鱼腥草、薄荷、罂粟壳（蜜炙）、甘草（蜜炙）。 | E27: 本品为红棕色至棕褐色的液体；气芳香，味微甜。 | F27: 疏风宣肺，止咳化痰。用于咳嗽属风邪犯肺证，症见咳嗽、咽痒、鼻塞流涕、恶寒发热、咯痰等。 | G27: 口服。每次20毫升，一日3次。 | H27: 尚不明确。 | I27: 尚不明确。 | J27: 1忌烟、酒及辛辣、生冷、油腻食物。 2不宜在服药期间同时服用滋补性中药。 3支气管扩张、肺脓疡、肺心病、肺结核患者出现咳嗽时应去医院就诊。 4糖尿病患者及有高血压、心脏病、肝病、肾病等慢性病严重者应在医师指导下服用。 5尚未有孕妇、儿童临床应用的研究资料。哺乳期妇女、年老体弱者应在医师指导下服用。 6服药期间，若患者发热体温超过38.5℃，或出现喘促气急者，或咳嗽加重、痰量明显增多者应去医院就诊。 7严格按用法用量服用，本品不宜长期服用。 8服药3天症状无缓解，应去医院就诊。 9对本品过敏者禁用，过敏体质 | L27: 如与其他药物同时使用可能会发生药物相互作用，详情请咨询医师或药师。 | N27: 密封。 | O27: 20ml/支;100ml/瓶 | Q27: 24月
A28: 通用名称：桑菊感冒片 商品名称：同仁堂 英文名称：SangJuGanMaoPian(TongRenTang) 汉语拼音：Sanju Ganmao Pian | B28: 11.4 | C28: =IF(ISNUMBER(MATCH(#REF!,非处方药名称!A:A,0)),"非处方药","处方药") -> 处方药 | D28: 桑叶、菊花、连翘、苦杏仁、桔梗、芦根、薄荷油、甘草。 | E28: 本品为淡棕色至棕褐色的片；气微香，味微苦。 | F28: 疏风清热，宣肺止咳。用于风热感冒初起，头痛，咳嗽，口干，咽痛。 | G28: 口服。一次4-8片，一日2-3次。 | H28: 尚不明确。 | I28: 尚不明确。 | J28: 1 忌烟、酒及辛辣、生冷、油腻食物。 2 不宜在服药期间同时服用滋补性中药。 3 风寒感冒者不适用。 4 有高血压、心脏病、肝病、糖尿病、肾病等慢性病严重者应在医师指导下服用。 5 儿童、孕妇、哺乳期妇女、年老体弱及脾虚便溏者应在医师指导下服用。 6 服药3天症状无缓解，应去医院就诊。 7 对本品过敏者禁用，过敏体质者慎用。 8 本品性状发生改变时禁止使用。 9 儿童必须在成人监护下使用。 10 请将本品放在儿童不能接触的地方。 11 如正在使用其他药品，使用本品前请咨询医师或药师。 | L28: 如与其他药物同时使用可能会发生药物相互作用，详情请咨询医师或药师。 | N28: 密封，置于阴凉处。 | O28: 素片：每片重0.6克；薄膜衣片：每片重0.62克 | P28: 塑料瓶装，每瓶装40片，0.6g*40s*2瓶/套，0.6g*40s*5瓶/套 | Q28: 36个月
A29: 通用名称：复方草珊瑚含片 商品名称：江中 英文名称：FuFangCaoShanHuHanPian(JiangZhong) 汉语拼音：Fu Fang Cao Shan Hu Han Pian | B29: 5.7 | C29: =IF(ISNUMBER(MATCH(#REF!,非处方药名称!A:A,0)),"非处方药","处方药") -> 处方药 | D29: 肿节风、薄荷脑、薄荷素油。 | E29: 本品为粉红色至棕红色的薄膜衣片，气香、味甜、清凉。 | F29: 疏风清热，消肿止痛，清利咽喉。用于外感风热所致的咽喉肿痛，声哑失音；急性咽喉炎属风热证者。 | G29: 含服。一次2片(小片)，每隔2小时一次，一日6次；或一次1片(大片)，每隔2小时1次，一日5～6次。 | H29: 尚不明确。 | I29: 对本药品过敏者禁用。 | J29: 1 忌烟酒、辛辣、鱼腥食物。 2 不宜在服药期间同时服用滋补性中药。 3 有高血压、心脏病、肝病、糖尿病、肾病等慢性病严重者应在医师指导下服用。 4 儿童、孕妇、哺乳期妇女、年老体弱、脾虚便溏者应在医师指导下服用。 5 声哑失音较重者，应及时去医院就诊。 6 服药3天症状无缓解，应去医院就诊。 7 对本品过敏者禁用，过敏体质者慎用。 8 本品性状发生改变时禁止使用。 9 儿童必须在成人监护下使用。 10 请将本品放在儿童不能接触的地方。 11 如正在使用其他药品，使用本品前请咨询医师或药师。 | L29: 如与其他药物同时使用可能会发生药物相互作用，详情请咨询医师或药师。 | M29: 疏风清热，消肿止痛，清利咽喉。 | N29: 密封。 | O29: 每片重0.44克(小片) | P29: PVC铝箔，每板装12片，每盒装4板，PVC铝箔，12s*10板/盒
A30: 通用名称：耳聋左慈丸 商品名称：同仁堂 英文名称：ErLongZuoCiWan 汉语拼音：Er long Zuo ci Wan | B30: 15.8 | C30: =IF(ISNUMBER(MATCH(#REF!,非处方药名称!A:A,0)),"非处方药","处方药") -> 处方药 | D30: 磁石(煅)、熟地黄、山茱萸(制)、山药、牡丹皮、泽泻、茯苓、竹叶柴胡。 | E30: 本品为棕黑色的浓缩丸；味甘、微酸。 | F30: 滋肾平肝。用于肝肾阴虚的耳鸣耳聋，头晕目眩。 | G30: 口服。一次8丸，一日3次。 | H30: 尚不明确。 | I30: 尚不明确。 | J30: 1.忌烟酒、辛辣刺激性食物。 2.感冒时不宜服用。 3.有高血压、心脏病、肝病、糖尿病、肾病等慢性病严重者应在医师指导下服用。 4.儿童、孕妇、哺乳期妇女、年老体弱者应在医师指导下服用。 5.本品只用于肝肾阴虚证之听力逐渐减退，耳鸣如蝉声者，凡属外耳、中耳病变而出现的耳鸣，如外耳道异物等，应去医院就诊。 6.突发耳鸣耳聋者应去医院就诊。 7.服药2周症状无缓解，应去医院就诊。 8.对本品过敏者禁用，过敏体质者慎用。 9.本品性状发生改变时禁止使用。 10.儿童必须在成人监护下使用。 11.请将本品放在儿童不能接触的地方。 12.如正在使用其他药品，使用本品前请咨询医师或药师。 | K30: 儿童注意事项： 应在医师指导下服用。 妊娠与哺乳期注意事项： 应在医师指导下服用。 老人注意事项： 应在医师指导下服用。 | L30: 如与其他药物同时使用可能会发生药物相互作用，详情请咨询医师或药师。 | N30: 密封，防潮 | O30: 每10丸重1g | P30: 每丸重0.19g，每瓶装60g。
A31: 通用名称：鼻渊通窍颗粒 商品名称：鲁南 英文名称：BiYuanTongQiaoKeLi(LuNan) 汉语拼音：Biyuan Tongqiao Keli | B31: 21.6 | C31: =IF(ISNUMBER(MATCH(#REF!,非处方药名称!A:A,0)),"非处方药","处方药") -> 处方药 | D31: 辛夷、苍耳子(炒)、麻黄、白芷、薄荷、藁本、黄芩、连翘、野菊花、天花粉、地黄、丹参、茯苓、甘草。 | E31: 本品为棕色至棕褐色的颗粒；气微香，味甜、微苦。 | F31: 疏风清热，宣肺通窍。用于急鼻渊（急性鼻窦炎）属外邪犯肺证，症见前额或颧骨部压痛，鼻塞时作，流涕黏白或黏黄，或头痛，或发热，苔薄黄或白，脉浮。 | G31: 开水冲服。一次1袋，一日3次。 | H31: 偶见腹泻。 | I31: 尚不明确。 | J31: 需在医生指导下用药；脾虚腹胀者慎用；服药期间勿食辛、辣等食物。 | L31: 如与其他药物同时使用可能发生药物相互作用，详情请咨询医师或药师。 | M31: 药理试验表明，本品对组胺和5-羟色胺所致的大鼠毛细血管通性增高、大鼠皮下棉球肉芽肿增生有一定的抑制作用；可增加小鼠碳粒廓清能力，促进环磷酰胺所致免疫功能低下小鼠的血清溶血素生成。 | N31: 密闭，防潮。 | O31: (1)每袋装10克(2)每袋装15克 | P31: 铝塑和服袋装，每盒装10袋，15g*15袋/盒，15g*21袋/盒，15g*10袋+1.2g*30s*1瓶/套，15g*10袋+1.2g*30s*1瓶/套，15g*10袋+1000mg*30s/套，，，
A32: 通用名称：冰珍去翳滴眼液 商品名称：白内停 英文名称：BingZhenQuYiDiYanYe(BaiNeiTing) 汉语拼音：Bingzhenquyi Diyanye | B32: 31.6 | C32: =IF(ISNUMBER(MATCH(#REF!,非处方药名称!A:A,0)),"非处方药","处方药") -> 处方药 | D32: 冰片、珍珠等 | E32: 本品为液状。 | F32: 去翳明目。用于老年性白内障初发期。 | G32: 滴于眼睑内，一次1～2滴，一日3～4次，滴眼后闭目2～3分钟。 | H32: 偶尔有轻度蛰样刺激感。 | I32: 眼部有创伤及溃疡者禁用。 | J32: 1.本品为外用滴眼药，禁止内服。 2.忌烟、酒、辛辣刺激性食物。 3.眼部有炎症者慎用。 4.用药后有眼痒，眼睑皮肤潮红，眼胀或过敏现象者停用，并到医院就诊。 5.如视力下降明显应到医院就诊。 6.治疗过程中局部出现炎症反应，立即停药并到医院就诊。 7.打开瓶盖后，15天内用完。 8.对本品过敏者禁用，过敏体质者慎用。 9.药品性状发生改变时禁止使用。 10.请将此药品放在儿童不能接触的地方。 11.如正在使用其他药品，使用本品前请咨询医师或药师。 | K32: 儿童注意事项： 尚不明确。 妊娠与哺乳期注意事项： 尚不明确。 老人注意事项： 尚不明确。 | L32: 如与其他药物同时使用可能会发生药物相互作用，详情请咨询医师或药师。 | M32: 尚不明确 | N32: 遮光，密闭保存。 | O32: 10ml | Q32: 24月
A33: 通用名称：雷公藤多苷片 商品名称：千金协力 英文名称：Tripterygium Glycosides 汉语拼音：Leigongtengduogan Pian | B33: 19.5 | C33: =IF(ISNUMBER(MATCH(#REF!,非处方药名称!A:A,0)),"非处方药","处方药") -> 处方药 | D33: 本品主要成分为雷公藤多甙。 | E33: 本品为浅黄色片；味微苦、涩 | F33: 祛风解毒、除湿消肿、舒筋通络。有抗炎及抑制细胞免疫和体液免疫等作用。用于风湿热瘀，毒邪阻滞所致的类风湿性关节炎，肾病综合症，白塞氏三联症，麻风反应，自身免疫性肝炎等。 | G33: 口服。每日每千克体重1～1．5毫克，分3次饭后服。一般首次应给足量，控制症状后减量。宜在医师指导下服用。 | H33: 1.消化系统：口干、恶心、 呕吐、乏力、食欲不振、腹胀、腹泻、黄疽、转氨酶升高；严重者可出现急性中毒性肝损伤、胃出血。2.血液系统：白细胞，血小板下降；严重者可出现粒细胞缺乏和全血细胞减少。3.泌尿系统：少尿或多尿、水肿、肾功能异常等肾脏损害；严重者可出现急性肾功能衰竭。4.心血管系统：心悸、胸闷、心律失常、血压升高或下降、心电图异常。5.生殖、内分泌系统：女子月经紊乱、月经量少或闭经；男子梢子数量减少、活力下降。6.神经系统：头昏、头辇、嗜睡，失眠、神经炎、复视。7.其他：皮疹、瘙痒、脱发、面部色素沉着。 | I33: 1.儿童、育龄期有孕育要求者、孕妇和哺乳期妇女禁用。 2.心、肝、肾功能不全者禁用;严重贫血、白细胞和血小板降低者禁用。 3.胃、十二指肠溃疡活动期患者禁用。 4.严重心律失常者禁用。 | J33: 1.服药期间可引起月经紊乱，精子活力及数目减少，白细胞及血小板减少，停药后可恢复。2.有严重心脑血管和老年患者慎用。3.孕妇忌用。4.本品在医生指导下严格按照说明书规定剂量用药，不可超量使用。5.用药期间应注意定期随诊并检査血、尿常规及心电图和肝肾功能，必要时停药并给予相应处理。6.连续用药一般不宜超过3个月。如继续用药，应由医生根据患者病情及治疗需要决定。 | K33: 儿童注意事项： 儿童禁用。 妊娠与哺乳期注意事项： 育龄期有孕育要求者、孕妇和哺乳期妇女禁用。 老人注意事项： 老年患者慎用。 | L33: 如与其他药物同时使用可能会发生药物相互作用，详情请咨询医师或药师。 | M33: 本品具有较强的抗炎及免疫抑制作用。在抗炎作用方面，它能拮抗和抑制炎症介质的释放、实验性炎症及关节炎的反应程度。在抑制免疫作用方面，它能抑制体液免疫和细胞免疫反应。 | N33: 避光、置阴凉(不超过20℃)干燥处密闭保存。 | O33: 10毫克 | P33: 口服固体药用高密度聚乙烯瓶包装。每瓶50片。 | Q33: 48个月。
A34: 通用名称：双氯芬酸钠滴眼液 商品名称：迪非 英文名称：Diclofenac Sodium Eye Drops 汉语拼音：Shuanglvfensuanna Diyanye | B34: 17.6 | C34: =IF(ISNUMBER(MATCH(#REF!,非处方药名称!A:A,0)),"非处方药","处方药") -> 处方药 | D34: 主要成分为双氯芬酸钠，化学名称为2-[(2,6-二氯苯基)氨基]苯乙酸钠。 | E34: 本品为无色或微黄色澄明水溶液。 | F34: 1.用于治疗葡萄膜炎、角膜炎、巩膜炎，抑制角膜新生血管的形成，治疗眼内手术后、激光滤帘成形术后或各种眼部损伤的炎症反应，抑制白内障手术中缩瞳反应；2.用于准分子激光角膜切削术后止痛及消炎；春季结膜炎、季节过敏性结膜炎等过敏性眼病，预防和治疗白内障及人工晶体术后炎症及黄斑囊样水肿，以及青光眼滤过术后促进滤过泡形成等。 | G34: 一日4～6次，一次1滴；眼科手术用药：术前3、2、1和0.5小时各滴眼一次，一次1滴。白内障术后24小时开始用药，一日4次，持续用药二周；角膜屈光术后15分钟即可用药，一日4次，持续用药三天。 | H34: 滴眼有短暂烧灼、刺痛、流泪等，极少数可有结膜充血、视物模糊。不足3%患者可出现乏力、困倦、恶心等全身反应。 | I34: 对本品过敏者禁用。 | J34: 1.本品仅限于滴眼用。 2.本品可妨碍血小板凝聚，有增加眼组织术中或术后出血的倾向。 3.戴接触镜者禁用本品，但角膜屈光术后暂时配戴治疗性亲水软镜者除外。 | K34: 儿童注意事项： 本品在儿童的安全性和作用尚未考察。 妊娠与哺乳期注意事项： 在动物致畸研究中，给小鼠用药量至人局部用量的5000倍(20mg/kg/day)，大鼠和兔用至2500倍（10mg/kg/day），均未发现致畸作用，尽管这些量已经达到对母体和胎儿产生毒性。大鼠母体对双氯芬酸钠的毒性表现为难产，妊娠延长，胎儿体重、生长和成活率下降。已经显示，双氯芬酸钠可透过大鼠和小鼠的胎盘屏障。但目前尚无在人体的研究报告，因此孕妇应慎用。 老人注意事项： 尚不明确。 | L34: 尚不明确。 | M34: 双氯芬酸钠是一种衍生于苯乙酸类的非甾体消炎镇痛药，其作用机理为抑制环氧化酶活性，从而阻断花生四烯酸向前列腺素的转化。同时，它也能促进花生四烯酸与甘油三脂结合，降低细胞内游离的花生四烯酸浓度，而间接抑制白三烯的合成。动物实验证实，前列腺素是引起眼内炎症的介质之一，能导致血-房水屏障崩溃、血管扩张、血管通透性增加、白细胞趋化、非胆碱能机制性瞳孔缩小等。双氯芬酸钠是非甾体消炎药中作用较强的一种，它对前列腺素合成的抑制作用强于阿司匹林和消炎痛等。双氯芬酸钠滴眼液对机械、化学、生物等刺激引起的血-房水屏障崩溃有较强的抑制作用。临床研究显示，0.1%双氯芬酸钠治疗白内障术后炎症，可降低前房的闪辉和细胞数；应用于角膜放射状切开术或激光屈光角膜切削术的病人，能缓解术后疼痛和畏光，优于安慰剂 | N34: 置凉暗处密闭保存。 | O34: 5毫升:5毫克 | Q34: 24个月
A35: 通用名称：马来酸噻吗洛尔滴眼液 商品名称：五景 英文名称：Timolol Maleate Eye Drops 汉语拼音：Malaisuansaimaluoer Diyanye | B35: 8.3 | C35: =IF(ISNUMBER(MATCH(#REF!,非处方药名称!A:A,0)),"非处方药","处方药") -> 处方药 | D35: 本品主要成份为：马来酸噻吗洛尔。其化学名称为：(-)-1-(叔丁氨基)-3-[(4-吗啉基-1,2,5-噻二唑-3-基)氧]-2-丙醇顺丁烯二酸盐。分子式：C13H24N4O3SC4H4O4分子量：432.49 | E35: 本品为无色的澄明液体。 | F35: 对原发性开角型青光眼具有良好的降低眼内压疗效。对于某些继发性青光眼，高眼压症，部分原发性闭角型青光眼以及其他药物及手术无效的青光眼，加用本品滴眼可进一步增强降眼压效果。 | G35: 滴眼，一次1滴，一日1～2次，如眼压已控制，可改为一日1次。如原用其他药物，在改用本品治疗时，原药物不易突然停用，应自滴用本品的第二天起逐渐停用。 | H35: 1 最常见的不良反应是眼烧灼感及刺痛。 2 心血管系统：心动过缓，心率失常。 3 神经系统：头晕，加重重症肌无力的症状，感觉异常，嗜睡，失眠，恶梦，抑郁，精神错乱，幻觉。 4 呼吸系统：支气管痉挛，呼吸衰竭，呼吸困难，鼻腔充血，咳嗽，上呼吸道感染。 5 内分泌系统：掩盖糖尿病患者应用胰岛素或降糖药后的低血糖症状。 | I35: 1 支气管哮喘者或有支气管哮喘史者，严重慢性阻塞性肺部疾病。 2 窦性心动过缓，Ⅱ或Ⅲ度房室传导阻滞，明显心衰，心源性休克。 3 对本品过敏者。 | J35: 1 当出现呼吸急促、脉搏明显减慢、过敏等症状时，请立即停止使用本品。 2 使用中若出现脑供血不足症状时应立即停药。 3 心功能损害者，使用本品时应避免服用钙离子拮抗剂。 4 对无心衰史的患者，如出现心衰症状应立即停药。 5 正在服用儿茶酚胺耗竭药（如利血平）者，使用本品时应严密观察。 6 冠状动脉疾患、糖尿病、甲状腺机能亢进和重症肌无力患者，用本品滴眼时需遵医嘱。 7 本品慎用于自发性低血糖患者及接受胰岛素或口服降糖药治疗的患者，因&beta;受体阻滞剂可掩盖低血糖症状。 8 本品不易单独用于治疗闭角型青光眼。 9 与其他滴眼液联合使用时，请间隔10分钟以上。 10 定期复查眼压，根据眼压变化调整用药方案。 11 用前应摇匀，避免容器尖端接触眼睛，防止滴眼液污染。 | K35: 儿童注意事项： 未进行该项实验且无可靠参考文献。 妊娠与哺乳期注意事项： 本品对于孕妇的安全性尚未确定。 滴眼后可在哺乳期妇女乳汁中测到本品，因对授乳婴儿具有多种潜在不良反应，需根据滴用本品对母亲的重要性决定终止哺乳或终止用药。 老人注意事项： 未进行该项实验且无可靠参考文献。 | L35: 1 与肾上腺素合用可引起瞳孔扩大。 2 不主张两种局部&beta;受体阻断剂同时应用。 3 本品与钙通道拮抗剂合用应慎重，因可引起房室传导阻滞，左心室衰竭及低血压。对心功能受损的患者，应避免两种药合并使用。 4 正在服用儿茶酚胺耗竭药（如利血平）者，使用本品时应严密观察，因可引起低血压和明显的心动过缓。 5 本品与洋地黄类和钙通道拮抗剂合用可进一步延长房室传导时间。 6 本品与奎宁丁合用能引起心率减慢等全身&beta;受体阻断的副作用。可能的原因是奎宁丁可抑制P450酶和CYPZD6对噻吗洛尔的代谢作用。 | M35: 马来酸噻吗洛尔是一种非选择性&beta;-肾上腺能受体阻滞剂，没有明显的内源性拟交感活性和局麻作用，对心肌无直接抑制作用。本品为马来酸噻吗洛尔滴眼剂，对高眼压患者和正常人均有降低眼内压作用。其降低眼内压的确切机理尚不清楚，眼压描记和房水荧光光度研究提示本品的降眼压作用与减少房水生成有关。非临床毒理研究：致癌性：动物实验显示长期大量口服马来酸噻吗洛尔可使雄性大鼠肾上腺嗜铬细胞瘤，雌性小鼠良性及恶性肺部肿瘤，良性子宫息肉及乳腺癌的发生率明显增高。生殖毒性：动物实验显示大剂量口服马来酸噻吗洛尔，对雄、雌性小鼠的生殖功能均无影响。 | N35: 室温下，避光贮存。 | O35: 5毫升:25毫克 | Q35: 24个月
A36: 通用名称：复方门冬维甘滴眼液 商品名称：新乐敦 英文名称：Compound Aspartate，Vitamin B6 and Dipotassium Glycyrrhetate Eye Drops 汉语拼音：WeiAnlin Diyanye | B36: 54 | C36: =IF(ISNUMBER(MATCH(#REF!,非处方药名称!A:A,0)),"非处方药","处方药") -> 处方药 | D36: 本品为复方制剂，每10毫升含门冬氨酸78毫克、维生素B65毫克、甘草酸二钾10毫克、盐酸萘甲唑林0.3毫克、甲硫酸新斯的明0.5毫克、马来酸氯苯那敏1毫克。辅料为：泛醇、薄荷脑、苯扎氯铵、吐温-80。 | E36: 本品为微黄色的澄明液体。 | F36: 用于抗眼疲劳，减轻结膜充血症状。 | G36: 滴眼，一次1-2滴，一日4-6次。 | H36: 偶见一过性刺激症状，不影响治疗。 | I36: 尚不明确。 | J36: 1.本品仅供眼用，切忌口服。 2.闭角型青光眼慎用。 3.滴眼时，瓶口勿接触手和眼睛，避免污染。 4.在使用过程中，如发现眼红、疼痛等情况，应停药就医。 5.使用后应将瓶盖拧紧以免污染药品。 6.对本品过敏者禁用，过敏体质者慎用。 7.本品性状发生改变时禁止使用。 8.请将本品放在儿童不能接触的地方。 9.儿童必须在成人监护下使用。 10.如正在使用其他药品，使用本品前请咨询医师或药师。 | K36: 儿童注意事项： 尚未明确。 妊娠与哺乳期注意事项： 尚未明确。 老人注意事项： 尚未明确。 | L36: 如与其他药物同时使用可能会发生药物相互作用，详情请咨询医师或药师。 | M36: 本品所含门冬氨酸、维生素B6在糖、蛋白质、脂肪代谢中起重要作用，可维持角膜与虹膜、睫状体的新陈代谢。甘草酸二钾具有抗炎、抗过敏作用。盐酸萘甲唑林为血管收缩剂，可减轻炎症和充血。马来酸氯苯那敏为抗组胺药，可缓解过敏反应症状。甲硫酸新斯的明为抗胆碱酯酶药，具有拟胆碱作用，可降低眼压，调节视力以及解除眼肌疲劳。 | N36: 密闭保存。 | O36: 13毫升 | Q36: 36个月
A37: 通用名称：盐酸左西替利嗪片 商品名称：迪皿 英文名称：Levocetirizine Hydrochloride Tablets 汉语拼音：Yansuan Zuoxitiliqin Pian | B37: 19 | C37: =IF(ISNUMBER(MATCH(#REF!,非处方药名称!A:A,0)),"非处方药","处方药") -> 处方药 | D37: 本品主要成分为盐酸左西替利嗪。 | E37: 本品为类白色片。 | F37: 荨麻疹、过敏性鼻炎、湿疹、皮炎、皮肤瘙痒症等。 | G37: 口服，成人及6岁以上儿童用量为每日一次，每次1片。2-6岁儿童，每日一次，每次半片。 | H37: 本品耐受性良好，不良反应轻微且多可自愈，常见不良反应有嗜睡、口干、头痛、乏力等。 | I37: 对本品及其它辅料过敏者禁用。 | J37: 1.有肝功能障碍或障碍史者慎用。 2.高空作业、驾驶或操纵机器期间慎用。 3.避免与镇静剂同服。 4.酒后避免使用本品。 5.肾功能减损患者使用本品适当减量。 | K37: 儿童注意事项： 2周岁以下儿童用药的安全性尚未确定。 妊娠与哺乳期注意事项： 孕期及哺乳期妇女禁用本品。 老人注意事项： 通常老年人生理机能衰退，需慎用本品。 | L37: 尚无使用本品进行药物相互作用的研究。消旋西替利嗪与伪麻黄碱、西咪替丁、酮康唑、红霉素、阿奇霉素、格列吡嗪和安定间无相互作用。 | M37: 本品为口服选择性组胺H1受体拮抗剂。无明显抗胆碱和抗5-羟色胺作用，中枢抑制作用较小。 | N37: 遮光，密封，干燥处保存。 | O37: 5毫克 | Q37: 24个月
A38: 通用名称：复方熊胆滴眼液 商品名称：三顺 英文名称：FuFangXiongDanDiYanYe(SanShun) 汉语拼音：Fufang Xiongdan Diyanye | B38: 12.2 | C38: =IF(ISNUMBER(MATCH(#REF!,非处方药名称!A:A,0)),"非处方药","处方药") -> 处方药 | D38: 熊胆粉、天然冰片。辅料：硼砂、硼酸、氯化钠、尼泊金乙酯、羧甲基纤维素钠。 | E38: 本品为淡黄色混悬液；气清香，味苦。 | F38: 清热降火、明目退翳。用于肝火上炎、热毒伤络型之急性细菌性结膜炎，流行性角结膜炎。 | G38: 滴眼，每次1～2次，一日6次，或遵医嘱。 | H38: 尚不明确。 | I38: 尚不明确。 | J38: 滴眼前轻摇药瓶，滴后拧紧瓶盖，忌食辛辣油腻食物。 | L38: 尚不明确。 | M38: 药理作用：本品能促进电热所致家兔角膜烧伤所致角膜翳处的角膜上皮修复，缩短愈合时间并减轻并发的结膜炎症状。体外试验结果表明，本品能抑制腺病毒Ⅲ型和单纯疱疹病毒Ⅰ型的增殖和金黄色葡萄球菌的生长。 | N38: 密闭，置凉处。 | O38: 每瓶装5ml;每瓶装8ml | P38: 5ml/盒；8ml/盒。
A39: 通用名称：玻璃酸钠滴眼液 商品名称：联邦亮晶晶 英文名称：Sodium Hyaluronate Eye Drops 汉语拼音：Bolisuanna Tiyanye | B39: 30.3 | C39: =IF(ISNUMBER(MATCH(#REF!,非处方药名称!A:A,0)),"非处方药","处方药") -> 处方药 | D39: 本品主要成分为透明质酸钠。 | E39: 本品为无色澄明的粘稠液体。 | F39: 眼睛疲劳、眼干燥症、眼干燥综合症、斯-约二氏综合症等内因性疾患。手术后药物性、外伤、光线对眼造成的刺激及戴隐形眼镜等引起的外因性疾病。 | G39: 一般一次1滴，1天滴眼5～6次，可根据症状适当增减。一般使用0.1％浓度的玻璃酸钠滴眼液，重症疾患以及效果不明显时使用0.3％的玻璃酸钠滴眼液。 | H39: 1.过敏症：有时可能会发生眼睑炎、眼睑皮肤炎等，出现上述症状应停药。2.有时可能会出现搔痒感、刺激感、充血、弥漫性表层角膜炎等角膜障碍，出现上述症状时应停药。 | I39: 尚未发现。 | J39: 1.过敏症：有时可能会发生眼睑炎、眼睑皮肤炎等，出现上述症状应停药。2.有时可能会出现搔痒感、刺激感、充血、弥漫性表层角膜炎等角膜障碍，出现上述症状时应停药。 | K39: 儿童注意事项： 尚不明确。 妊娠与哺乳期注意事项： 尚不明确。 老人注意事项： 尚不明确。 | L39: 尚不明确。 | M39: 玻璃酸钠是一种线性多糖，广泛存在于脊椎动物的结缔组织基质中。玻璃酸钠能与纤维连结蛋白结合，加速上皮细胞的粘附和延展；由于玻璃酸钠分子能存留大量水分子而具有较好的保水作用。家兔试验提示，局部应用玻璃酸钠可一定程度促进角膜上皮损伤的愈合。体外试验提示，玻璃酸钠能加速培养的家兔角膜片中结膜上皮细胞的延展，具有防止离体家兔结膜片干燥的作用。 | N39: 遮光、密闭2～8℃下保存。 | O39: (1)5毫升:5毫克;(2)7毫升:7毫克 | P39: 塑料瓶装，每小盒1瓶，(1)每瓶5ml （2）每瓶7ml。 | Q39: 24月
A40: 通用名称：重组人表皮生长因子滴眼液(酵母) 商品名称：易贝 英文名称：Recombinant Human Epidermal Growth Factor Eye Drops(Yeast) 汉语拼音：Chongzu renbiaopishengzhangyinzi diyanye | B40: 35.4 | C40: =IF(ISNUMBER(MATCH(#REF!,非处方药名称!A:A,0)),"非处方药","处方药") -> 处方药 | D40: 主酵母表达的重组人表皮生长因子(rhEGF)。 | E40: 本品为无色澄清液。 | F40: 各种原因引起的角膜上皮缺损，包括角膜机械性损伤、各种角膜手术后、轻度干眼症伴浅层点状角膜病变、轻度化学烧伤等。 | G40: 将本品直接滴入 眼 结膜囊内，每次 1―2滴，每日4次，或遵医嘱。 | H40: 未观察到局部刺激现象及全身性不良反应。 | I40: 对天然和重组 hEGF、甘油、甘露醇有过敏史者禁用。 | J40: 1.需根据病情，合并应用抗生素或抗病毒药物，针对病因进行治疗。 2.使用过程中应避免污染。 3.本品应在开启后一周内用完。 | K40: 儿童注意事项： 尚不清楚。 妊娠与哺乳期注意事项： 尚不清楚。 老人注意事项： 尚不清楚。 | L40: 未发现与其他药物有协同或拮抗作用。 | M40: 本品活性成份为重组人表皮生长因子（rhEGF）,可促进角膜上皮细胞的再生，从而缩短受损角膜的愈合时间。 | N40: 4-25℃保存。 | O40: 20000IU(40μg)/2ml/支;30000IU(60μg)/3ml/支;40000IU(80μg)/4ml/支 | Q40: 24个月
...

Sheet 非处方药名称
A1: 枸橼酸铋钾颗粒（非处方）
A2: 乳果糖口服溶液
A3: 铝碳酸镁片
A4: 麻仁软胶囊
A5: 通天口服液
A6: 藿香正气滴丸
A7: 麻仁润肠丸
A8: 固本益肠片
A9: 达立通颗粒
A10: 胃乃安胶囊
A11: 枸橼酸铋钾胶囊
A12: 丁桂儿脐贴（2贴装）
... A3117: 西瓜霜喉口宝含片

Sheet Sheet1
A1: 用法用量 | B1: 用法用量
A2: 温开水冲服 | B2: 温开水冲服。12岁以下儿童用量见下表：2～3岁， 12～14公斤， 0.5～1片/次， 一日3次4～6岁， 16～20公斤， 1～1.5片/次， 一日3次7～9岁， 22～26公斤， 1.5～2片/次， 一日3次10～12岁， 28～32公斤，2～2.5片/次， 一日3次
A3: 口服 | B3: 口服。成人，一次1片，一日2次。
A4: 滴眼 | B4: 滴眼，一日3次，一次1～2滴或遵医嘱。
A5: 开水冲服 | B5: 开水冲服。一岁以内一次6克，一岁至三岁一次612克，四岁至七岁一次12-18克，八岁至十二岁一次24克，一日2次。
A6: 含服 | B6: 含服。一次4～6粒，日3次。
A7: 口服 | B7: 口服。一次3～4片，一日3次。
A8: 口服 | B8: 口服。一次2袋，一日1～2次。
A9: 口服 | B9: 口服。一次1～2袋，一日2～3次。
A10: 口服 | B10: 口服。一次4粒，一日3次。
A11: 口服 | B11: 口服。一次2片，一日3次；或遵医嘱。该药品连服七日为一疗程，可以连续服用三至五个疗程。
A12: 口服 | B12: 口服。一次2粒，一日3次。
... A1152: 口服 | B1152: 口服。吞服或用少量水溶解后服用，成人一次20~40mg，一日3次，或遵医嘱。
A1153: 糖皮质激素在应用生理剂量替代治疗时无明显不良反应 | B1153: 糖皮质激素在应用生理剂量替代治疗时无明显不良反应，不良反应多发生在应用药理剂量时，而且与疗程、剂量、用药种类、用法及给药途径等有密切关系。常见不良反应有以下几类。 1.静脉迅速给予大剂量可能发生全身性的过敏反应，包括面部、鼻粘膜、眼睑肿胀，荨麻疹，气短，胸闷，喘鸣。长程用药可引起以下副作用：医源性柯兴综合征面容和体态、体重增加、下肢浮肿、紫纹、易出血倾向、创口愈合不良、痤疮、月经紊乱、肱或股骨头缺血性坏死、骨质疏松或骨折(包括脊椎压缩性骨折、长骨病理性骨折)、肌无力、肌萎缩、低血钾综合征、胃肠道刺激(恶心、呕吐)、胰腺炎、消化性溃疡或肠穿孔，儿童生长受到抑制、青光眼、白内障、良性颅内压升高综合征、糖耐量减退和糖尿病加重。 2.患者可出现精神症状：欣快感、激动、不安、谵妄、定向力障碍，也可表现为抑制。精神症状尤易发生于患慢性消耗性疾病的人及以往有过精神不正常者。在用量达每日强的松40mg或更多，用药数日至二周即可出现。并发感染为糖皮质激素的主要不良反应。以真菌、结核菌、葡萄球菌、变形杆菌、绿脓杆菌和各种疱疹病毒感染为主。多发生在中程或长程疗法时，但亦可在短期用大剂量后出现。 3.下丘脑-垂体-肾上腺轴受到抑制，为激素治疗的重要并发症，其发生与制剂、剂量、疗程等因素有关。每日用强的松20mg以上，历时3周以上，以及出现医源性柯兴综合征时，应考虑肾上腺功能已受到抑制。 4.糖皮质激素停药后综合征可有以下各种不同的情况。①下丘脑-垂体-肾上腺功能减退，可表现为乏力、软弱、食欲减退、恶心、呕吐、血压偏低、长程治疗后此轴心功能的恢复一般需要9～12个月，功能恢复的先后依次为：i.下丘脑促肾上腺皮质激素释放素(CRF)分泌恢复并增多;ii.ACTH分泌恢复并高于正常，此时肾上腺皮质激素的分泌仍偏低;iii.氢皮质素的基础分泌恢复正常、垂体ACTH的分泌由原来偏多而恢复正常;iV.下丘脑-垂体-肾上腺皮质轴对应激的反应恢复正常。②停药后原来疾病已被控制的症状重新出现。为了避免肾上腺皮质功能减退的发生及原来疾病症状的复燃，在长程激素治疗后应缓慢地逐渐减量，并由原来的一日服用数次，改为每日上午服药一次，或隔日上午服药一次。③糖皮质激素停药综合征。有时患者在停药后出现头晕、昏厥倾向、腹痛或背痛、低热、食欲减退、恶心、呕吐、肌肉或关节疼痛、头疼、乏力、软弱，经仔细检查如能排除肾上腺皮质功能减退和原来疾病的复燃，则可考虑为对糖皮质激素的依赖综合征。 5.大剂量长期使用可有肥胖，多毛症，痤疮，血糖，血压及眼压升高，水钠潴留，水肿。可引起低血钾，肌肉麻痹，兴奋，胃肠溃疡，甚至出现胃肠出血，穿孔，骨质疏松，病理性骨折，伤口不易愈合，白内障，失明。突然停药可引起停药综合征。 | H1153: 突然停药可引起停药综合征
A1154: 口服 | B1154: 口服。一次12克，一日3次，或遵医嘱。
A1155: 口服 | B1155: 口服。一次1格半至2格(15～20毫升)，一日3次；服时摇匀。
A1156: 口服 | B1156: 口服，每一次20克，一日3～5次。
A1157: 口服 | B1157: 口服。一次10～20毫升，一日3次。
A1158: 口服 | B1158: 口服。一次6～8片，一日3次。
A1159: 口服 | B1159: 口服。一次15克，一日3次。
A1160: 口服 | B1160: 口服。一次20毫升，一日3次。
A1161: 口服 | B1161: 口服。一次2粒，一日3次。
A1162: 含服 | B1162: 含服。一次1片，每隔1～2小时1次。
A1163: 口服 | B1163: 口服。一次10毫升，一日4次。
A1164: 口服 | B1164: 口服。一次5片，一日3次。
A1165: 口服 | B1165: 口服，一次1丸，一日2次，小儿酌减。
... A1340: 口服 | B1340: 口服。每次10毫升，每天2-3次。儿童酌减
A1341: 本品可用静脉滴注或深部肌肉注射给药 | B1341: 本品可用静脉滴注或深部肌肉注射给药。 成人和16岁以上儿童或体重为40公斤或40公斤以上儿童患者，可根据病情，每次1～2克，每12小时一次，静脉滴注，疗程7～10天；轻中度尿路感染，每次0.5～1克，静脉滴注或深部肌肉注射，疗程7～10天；重度尿路感染，每次2克，每12小时一次，静脉滴注，疗程10天；对于严重感染并危及生命时，可以每8小时2克静脉滴注；用于中性粒细胞减少伴发热的经验治疗，每次2克，每8小时一次静脉滴注，疗程7～10天或至中性粒细胞减少缓解。如发热缓解但中性粒细胞仍处于异常低水平，应重新评价有无继续使用抗生素治疗的必要。 2月龄至12岁儿童，最大剂量不可超过成人剂量（即每次2克剂量）。体重超过40公斤的儿童的剂量，可使用成人剂量。一般可每公斤体重40毫克，每12小时静脉滴注，疗程7～14天；对细菌性脑脊髓膜炎儿童患者，可为每公斤体重50毫克，每8小时一次，静脉滴注。对儿童中性粒细胞减少伴发热经验治疗的常用剂量为每公斤体重50毫克，每12小时一次（中性粒细胞减少伴发热的治疗为每8小时一次），疗程与成人相同。 2月龄以下儿童经验有限。可使用每公斤体重50毫克剂量。然而2月龄以上儿童患者的资料表明，每公斤30毫克，每8或12小时一次对于1至2月龄儿童患者已经足够。对2月龄以下儿童使用本品应谨慎。 儿童深部肌肉注射的经验有限。 对肝功能不全患者，无调节本品剂量的必要。 对肾功能不全病人，如肌酐清除率低于（含）60ml/min，则应调节本品用量，弥补这些病人减慢的肾清除速率。这些病人使用头孢吡肟的初始剂量与肾功能正常的患者相同，维持剂量和给药间隙时间如下： 与正常给药方案比较，肾功能不全成人患者的推荐维持给药方案 肌酐清除率（ml/min） 推荐维持给药方案 ＞60， 每次0.5克， 每次1克， 每次2克， 每次2克， 正常给药方案 每12小时一次 每12小时一次 每12小时一次 每8小时一次 30-60 每次0.5克， 每次1克， 每次2克， 每次2克， 每24小时一次 每24小时一次 每24小时一次 每24小时一次 11-29 每次0.5克， 每次0.5克， 每次1克， 每次2克， 每24小时一次 每24小时一次 每24小时一次 每24小时一次 ＜11 每次0.25克， 每次0.25克， 每次0.5克， 每次1克， 每24小时一次 每24小时一次 每24小时一次 每24小时一次 血液透析* 每次0.5克， 每次0.5克， 每次0.5克， 每次0.5克， 每24小时一次 每24小时一次 每24小时一次 每24小时一次 *血液透析患者在治疗第一天可给予负荷剂量1克，以后每天0.5克。透析日，头孢吡肟应在透析结束后使用。每天给药时间尽可能相同。 头孢吡肟治疗同时需进行血液透析的患者，在透析开始3小时，约68％药物可被清除。血液透析患者的马斯平剂量见上表。接受持续性腹膜透析患者应每隔48小时给予常规剂量。 尚无肾功能不全的儿童患者使用头孢吡肟的资料。但是，由于成人和儿童的头孢吡肟药代动力学相似，肾功能不全儿童患者头孢吡肟的用法与成人类似。 静脉给药：对于严重或危及生命的病例，应首选静脉给药。 静脉滴注时，可将本品1～2克溶于50～100毫升0.9%氯化钠注射液，5%或10%葡萄糖注射液，M/6乳酸钠注射液，5%葡萄糖和0.9%氯化钠混合注射液，乳酸林格氏和%5葡萄糖混合注射液中，药物浓度不应超过每毫升40毫克。经约30分钟滴注完毕。 肌肉内注射：肌肉注射时，本品0.5克应加1.5毫升注射用溶液，或1克加3.0毫升溶解后，经深部肌群（如臀肌群或外侧股四头肌）注射。 | H1341: 尚无肾功能不全的儿童患者使用头孢吡肟的资料 | I1341: 但是，由于成人和儿童的头孢吡肟药代动力学相似，肾功能不全儿童患者头孢吡肟的用法与成人类似 | J1341: 静脉给药：对于严重或危及生命的病例，应首选静脉给药 | K1341: 静脉滴注时，可将本品1～2克溶于50～100毫升0.9%氯化钠注射液，5%或10%葡萄糖注射液，M/6乳酸钠注射液，5%葡萄糖和0.9%氯化钠混合注射液，乳酸林格氏和%5葡萄糖混合注射液中，药物浓度不应超过每毫升40毫克 | L1341: 经约30分钟滴注完毕 | M1341: 肌肉内注射：肌肉注射时，本品0.5克应加1.5毫升注射用溶液，或1克加3.0毫升溶解后，经深部肌群（如臀肌群或外侧股四头肌）注射
A1342: 口服 | B1342: 口服。一次6片，一日3次，饭后用温开水送服。
A1343: 用开水冲服 | B1343: 用开水冲服。一次5克，一日3次；小儿酌减。
A1344: 口服 | B1344: 口服，一次3克，一日1～2次
A1345: 日服 | B1345: 日服，一次15克，一日2次。
A1346: 口服 | B1346: 口服。一次0.2g，一日1次。首剂量加倍为0.4g。疗程5～10日。对前列腺炎的疗程可达4周。
A1347: 成人每次2.5g或5g（即哌拉西林2g或4g | B1347: 成人每次2.5g或5g（即哌拉西林2g或4g，舒巴坦0.5g或1g），每12小时一次。严重或难治性感染，每次2.5g或5g（即哌拉西林2g或4g，舒巴坦0.5g或1g），每8小时一次。肾功能不全者酌情调整剂量。疗程：7—14天，或根据病情需要调整疗程。
A1348: 本品可直接口服 | B1348: 本品可直接口服，也可以加10-15ml温开水中搅拌均匀后服用。成人一般每次0.25g（两包），每日两次，一般疗程为5-10日。儿童按体重每日20mg/kg，分两次服用，一日不超过0.5g。
A1349: 口服 | B1349: 口服。一次1.5～2.0克，一日2～3次，可在发病预兆前服用，也可预防久喘复发，一般服15天为一疗程。
A1350: 口服 | B1350: 口服，一次1支，一日2-3次。
A1351: 成人一次1片 | B1351: 成人一次1片，每日2次，儿童按体重计算（与牛奶同服，增加吸收和提高药效）。
A1352: 口服 | B1352: 口服。1～2岁 一次1/2袋，3～4岁 一次1袋，5～6岁 一次1.5袋，一日2次。
A1353: 口服 | B1353: 口服。成人及12岁以上儿童：一次10ml，1日3次，睡前服20ml。6-12岁儿童：一次5ml，1日3次，睡前服10ml。2-5岁儿童：一次2.5ml，1日3次，睡前服5ml。2岁以下儿童不宜服用。
...

Sheet Sheet2
A1: 属性名称 | B1: 抽取实体或属性 | C1: 属性名称 | D1: 抽取实体或属性
A2: 药品名称 | B2: 药品；用法；剂型 | C2: 注意事项 | D2: 特殊人群
A3: 指导价 | B3: 指导价（属性） | C3: 特殊人群用药 | D3: 特殊人群
A4: 处方药 | C4: 药物相互作用
A5: 成分 | B5: 成分 | C5: 药理作用
A6: 性状 | B6: 剂型 | C6: 贮藏
A7: 适应症 | B7: 功效或适应症 | C7: 规格
A8: 用法用量 | B8: 用法 | C8: 包装规格
A9: 不良反应 | C9: 有效期
A10: 禁忌 | B10: 特殊人群
A11: 注意事项 | B11: 特殊人群
A12: 特殊人群用药 | B12: 特殊人群
A13: 药物相互作用
A14: 药理作用
A15: 贮藏
A16: 规格
A17: 包装规格
A18: 有效期
